[2023-12-26T10:00:40.669+0000] {taskinstance.py:1957} INFO - Dependencies all met for dep_context=non-requeueable deps ti=<TaskInstance: load_data_to_redshift.load_task manual__2023-12-26T10:00:36.667118+00:00 [queued]>
[2023-12-26T10:00:40.678+0000] {taskinstance.py:1957} INFO - Dependencies all met for dep_context=requeueable deps ti=<TaskInstance: load_data_to_redshift.load_task manual__2023-12-26T10:00:36.667118+00:00 [queued]>
[2023-12-26T10:00:40.678+0000] {taskinstance.py:2171} INFO - Starting attempt 1 of 1
[2023-12-26T10:00:40.691+0000] {taskinstance.py:2192} INFO - Executing <Task(_PythonDecoratedOperator): load_task> on 2023-12-26 10:00:36.667118+00:00
[2023-12-26T10:00:40.697+0000] {standard_task_runner.py:60} INFO - Started process 15783 to run task
[2023-12-26T10:00:40.701+0000] {standard_task_runner.py:87} INFO - Running: ['***', 'tasks', 'run', 'load_data_to_redshift', 'load_task', 'manual__2023-12-26T10:00:36.667118+00:00', '--job-id', '40', '--raw', '--subdir', 'DAGS_FOLDER/redshift_data.py', '--cfg-path', '/tmp/tmpdgyflbjv']
[2023-12-26T10:00:40.702+0000] {standard_task_runner.py:88} INFO - Job 40: Subtask load_task
[2023-12-26T10:00:40.750+0000] {task_command.py:423} INFO - Running <TaskInstance: load_data_to_redshift.load_task manual__2023-12-26T10:00:36.667118+00:00 [running]> on host d3aa51350085
[2023-12-26T10:00:40.818+0000] {taskinstance.py:2481} INFO - Exporting env vars: AIRFLOW_CTX_DAG_OWNER='***' AIRFLOW_CTX_DAG_ID='load_data_to_redshift' AIRFLOW_CTX_TASK_ID='load_task' AIRFLOW_CTX_EXECUTION_DATE='2023-12-26T10:00:36.667118+00:00' AIRFLOW_CTX_TRY_NUMBER='1' AIRFLOW_CTX_DAG_RUN_ID='manual__2023-12-26T10:00:36.667118+00:00'
[2023-12-26T10:00:40.834+0000] {base.py:83} INFO - Using connection ID 'redshift' for task execution.
[2023-12-26T10:00:40.886+0000] {sql.py:432} INFO - Running statement: 
COPY trips
FROM 's3://gitongabretton/data-pipelines/divvy/unpartitioned/divvy_trips_2018.csv'
ACCESS_KEY_ID 'AKIATZS7MBBSL3CADLWH'
SECRET_ACCESS_KEY '***'
IGNOREHEADER 1
DELIMITER ','
, parameters: None
[2023-12-26T11:37:46.309+0000] {taskinstance.py:2699} ERROR - Task failed with exception
Traceback (most recent call last):
  File "/home/airflow/.local/lib/python3.8/site-packages/airflow/models/taskinstance.py", line 433, in _execute_task
    result = execute_callable(context=context, **execute_callable_kwargs)
  File "/home/airflow/.local/lib/python3.8/site-packages/airflow/decorators/base.py", line 242, in execute
    return_value = super().execute(context)
  File "/home/airflow/.local/lib/python3.8/site-packages/airflow/operators/python.py", line 199, in execute
    return_value = self.execute_callable()
  File "/home/airflow/.local/lib/python3.8/site-packages/airflow/operators/python.py", line 216, in execute_callable
    return self.python_callable(*self.op_args, **self.op_kwargs)
  File "/opt/airflow/dags/redshift_data.py", line 23, in load_task
    redshift_hook.run(sql_statements.COPY_ALL_TRIPS_SQL.format(aws_connection.login, aws_connection.password))
  File "/home/airflow/.local/lib/python3.8/site-packages/airflow/providers/common/sql/hooks/sql.py", line 392, in run
    self._run_command(cur, sql_statement, parameters)
  File "/home/airflow/.local/lib/python3.8/site-packages/airflow/providers/common/sql/hooks/sql.py", line 437, in _run_command
    cur.execute(sql_statement)
psycopg2.errors.InternalError_: S3CurlException: Failed to connect to s3.us-east-1.amazonaws.com port 443: Connection timed out, CurlError 28, multiCurlError 0, CanRetry 1, UserError 0
DETAIL:  
  -----------------------------------------------
  error:  S3CurlException: Failed to connect to s3.us-east-1.amazonaws.com port 443: Connection timed out, CurlError 28, multiCurlError 0, CanRetry 1, UserError 0
  code:      9002
  context:   Listing bucket=gitongabretton prefix=data-pipelines/divvy/unpartitioned/divvy_trips_2018.csv
  query:     413011[child_sequence:1]
  location:  s3_utility.cpp:702
  process:   padbmaster [pid=1073979644]
  -----------------------------------------------


[2023-12-26T11:37:46.319+0000] {taskinstance.py:1138} INFO - Marking task as FAILED. dag_id=load_data_to_redshift, task_id=load_task, execution_date=20231226T100036, start_date=20231226T100040, end_date=20231226T113746
[2023-12-26T11:37:46.332+0000] {standard_task_runner.py:107} ERROR - Failed to execute job 40 for task load_task (S3CurlException: Failed to connect to s3.us-east-1.amazonaws.com port 443: Connection timed out, CurlError 28, multiCurlError 0, CanRetry 1, UserError 0
DETAIL:  
  -----------------------------------------------
  error:  S3CurlException: Failed to connect to s3.us-east-1.amazonaws.com port 443: Connection timed out, CurlError 28, multiCurlError 0, CanRetry 1, UserError 0
  code:      9002
  context:   Listing bucket=gitongabretton prefix=data-pipelines/divvy/unpartitioned/divvy_trips_2018.csv
  query:     413011[child_sequence:1]
  location:  s3_utility.cpp:702
  process:   padbmaster [pid=1073979644]
  -----------------------------------------------

; 15783)
[2023-12-26T11:37:46.349+0000] {local_task_job_runner.py:234} INFO - Task exited with return code 1
[2023-12-26T11:37:46.375+0000] {taskinstance.py:3281} INFO - 0 downstream tasks scheduled from follow-on schedule check
