[2023-12-26T11:31:04.748+0000] {taskinstance.py:1957} INFO - Dependencies all met for dep_context=non-requeueable deps ti=<TaskInstance: final_project_dag.create_users_table manual__2023-12-26T11:31:00.224027+00:00 [queued]>
[2023-12-26T11:31:04.845+0000] {taskinstance.py:1957} INFO - Dependencies all met for dep_context=requeueable deps ti=<TaskInstance: final_project_dag.create_users_table manual__2023-12-26T11:31:00.224027+00:00 [queued]>
[2023-12-26T11:31:04.845+0000] {taskinstance.py:2171} INFO - Starting attempt 1 of 4
[2023-12-26T11:31:04.952+0000] {taskinstance.py:2192} INFO - Executing <Task(PostgresOperator): create_users_table> on 2023-12-26 11:31:00.224027+00:00
[2023-12-26T11:31:04.991+0000] {standard_task_runner.py:60} INFO - Started process 17170 to run task
[2023-12-26T11:31:05.022+0000] {standard_task_runner.py:87} INFO - Running: ['***', 'tasks', 'run', 'final_project_dag', 'create_users_table', 'manual__2023-12-26T11:31:00.224027+00:00', '--job-id', '67', '--raw', '--subdir', 'DAGS_FOLDER/final_project/final_project.py', '--cfg-path', '/tmp/tmpnkz2txoj']
[2023-12-26T11:31:05.049+0000] {standard_task_runner.py:88} INFO - Job 67: Subtask create_users_table
[2023-12-26T11:31:05.476+0000] {task_command.py:423} INFO - Running <TaskInstance: final_project_dag.create_users_table manual__2023-12-26T11:31:00.224027+00:00 [running]> on host d3aa51350085
[2023-12-26T11:31:05.908+0000] {abstractoperator.py:708} ERROR - Exception rendering Jinja template for task 'create_users_table', field 'sql'. Template: 'create_users_table.sql'
Traceback (most recent call last):
  File "/home/airflow/.local/lib/python3.8/site-packages/airflow/models/abstractoperator.py", line 700, in _do_render_template_fields
    rendered_content = self.render_template(
  File "/home/airflow/.local/lib/python3.8/site-packages/airflow/template/templater.py", line 171, in render_template
    template = jinja_env.get_template(value)
  File "/home/airflow/.local/lib/python3.8/site-packages/jinja2/environment.py", line 1010, in get_template
    return self._load_template(name, globals)
  File "/home/airflow/.local/lib/python3.8/site-packages/jinja2/environment.py", line 969, in _load_template
    template = self.loader.load(self, name, self.make_globals(globals))
  File "/home/airflow/.local/lib/python3.8/site-packages/jinja2/loaders.py", line 126, in load
    source, filename, uptodate = self.get_source(environment, name)
  File "/home/airflow/.local/lib/python3.8/site-packages/jinja2/loaders.py", line 218, in get_source
    raise TemplateNotFound(template)
jinja2.exceptions.TemplateNotFound: create_users_table.sql
[2023-12-26T11:31:05.918+0000] {taskinstance.py:2699} ERROR - Task failed with exception
Traceback (most recent call last):
  File "/home/airflow/.local/lib/python3.8/site-packages/airflow/models/taskinstance.py", line 2335, in _run_raw_task
    self._execute_task_with_callbacks(context, test_mode, session=session)
  File "/home/airflow/.local/lib/python3.8/site-packages/airflow/models/taskinstance.py", line 2466, in _execute_task_with_callbacks
    task_orig = self.render_templates(context=context)
  File "/home/airflow/.local/lib/python3.8/site-packages/airflow/models/taskinstance.py", line 2878, in render_templates
    original_task.render_template_fields(context)
  File "/home/airflow/.local/lib/python3.8/site-packages/airflow/models/baseoperator.py", line 1248, in render_template_fields
    self._do_render_template_fields(self, self.template_fields, context, jinja_env, set())
  File "/home/airflow/.local/lib/python3.8/site-packages/airflow/utils/session.py", line 79, in wrapper
    return func(*args, session=session, **kwargs)
  File "/home/airflow/.local/lib/python3.8/site-packages/airflow/models/abstractoperator.py", line 700, in _do_render_template_fields
    rendered_content = self.render_template(
  File "/home/airflow/.local/lib/python3.8/site-packages/airflow/template/templater.py", line 171, in render_template
    template = jinja_env.get_template(value)
  File "/home/airflow/.local/lib/python3.8/site-packages/jinja2/environment.py", line 1010, in get_template
    return self._load_template(name, globals)
  File "/home/airflow/.local/lib/python3.8/site-packages/jinja2/environment.py", line 969, in _load_template
    template = self.loader.load(self, name, self.make_globals(globals))
  File "/home/airflow/.local/lib/python3.8/site-packages/jinja2/loaders.py", line 126, in load
    source, filename, uptodate = self.get_source(environment, name)
  File "/home/airflow/.local/lib/python3.8/site-packages/jinja2/loaders.py", line 218, in get_source
    raise TemplateNotFound(template)
jinja2.exceptions.TemplateNotFound: create_users_table.sql
[2023-12-26T11:31:05.981+0000] {taskinstance.py:1138} INFO - Marking task as UP_FOR_RETRY. dag_id=final_project_dag, task_id=create_users_table, execution_date=20231226T113100, start_date=20231226T113104, end_date=20231226T113105
[2023-12-26T11:31:06.099+0000] {standard_task_runner.py:107} ERROR - Failed to execute job 67 for task create_users_table (create_users_table.sql; 17170)
[2023-12-26T11:31:06.187+0000] {local_task_job_runner.py:234} INFO - Task exited with return code 1
[2023-12-26T11:31:06.250+0000] {taskinstance.py:3281} INFO - 0 downstream tasks scheduled from follow-on schedule check
